Workbook

Sheet Sheet1
E1: Number | F1: Person | G1: Action | H1: Object | L1: 2 Digit Person | M1: 2 Digit Object
E2: - | F2: Magician | G2: Vanishing | H2: Wand
A3: 000-099 | B3: Real People | C3: 000-009 | D3: Family | E3: 0 | G3: Squeezing | H3: Void/Vacuum | I3: 0-9 | J3: Elements | L3: Zeus | M3: Sauce
E4: 1 | G4: Sitting | H4: Hydrogen | L4: Sid | M4: Seaweed
E5: 2 | G5: Snorting | H5: Helium | L5: Santa | M5: Sun
E6: 3 | G6: Swimming | H6: Lithium | L6: Sumo | M6: Seam
E7: 4 | G7: Searing | H7: Beryllium | L7: Seer | M7: Sword
E8: 5 | G8: Slapping | H8: Boron | L8: Saul | M8: Seal
E9: 6 | G9: Swishing | H9: Carbon | L9: Sasha | M9: Sushi
E10: 7 | G10: Sucking | H10: Nitrogen | L10: Zack | M10: Sock
E11: 8 | G11: Sieving | H11: Oxygen | L11: Sova | M11: Safe
E12: 9 | G12: Spitting | H12: Fluorine | L12: Superman | M12: Soap
C13: 010-019 | D13: Friends | E13: 10 | G13: Tazing | H13: Neon | I13: 10-19 | L13: Tas | M13: Daisy
E14: 11 | G14: Tattooing | H14: Sodium | L14: Dad | M14: Toad
E15: 12 | G15: Dancing | H15: Magnesium | L15: Tony | M15: Tin
E16: 13 | G16: Timing | H16: Aluminum | L16: Timmy | M16: Atom
E17: 14 | G17: Drawing | H17: Silicon | L17: Dora | M17: Door
E18: 15 | G18: Dueling | H18: Phosphorus | L18: Dali | M18: Towel
E19: 16 | G19: Dodging | H19: Sulfur | L19: Dwayne Johnson | M19: Tissue
E20: 17 | G20: Digging | H20: Chlorine | L20: Doc | M20: Taco
E21: 18 | G21: Diving | H21: Argon | L21: Tfue | M21: Dove
E22: 19 | G22: Tapping | H22: Potassium | L22: Dobby | M22: Tap
C23: 020-029 | D23: Friends 2 | E23: 20 | G23: Nosing | H23: Calcium | I23: 20-29 | L23: Nas | M23: News
E24: 21 | G24: Handing | H24: Scandium | L24: Knight | M24: Net
E25: 22 | G25: No-Noing | H25: Titanium | L25: Nun | M25: Onion
E26: 23 | G26: Enema-ing | H26: Vanadium | L26: Nami | M26: Gnome
E27: 24 | G27: Honoring | H27: Chromium | L27: Nurse | M27: Henry
E28: 25 | G28: Kneeling | H28: Manganese | L28: Nelson | M28: Nail
E29: 26 | G29: Noshing | H29: Iron | L29: Neji | M29: Nacho
E30: 27 | G30: Knocking | H30: Cobalt | L30: Nephew | M30: Ink
E31: 28 | G31: Knifing | H31: Nickel | L31: Nick Fury | M31: Knife
E32: 29 | G32: Napping | H32: Copper | L32: Napolean | M32: Knob
C33: 030-039 | D33: School Male | E33: 30 | G33: Missing | H33: Zinc | I33: 30-39 | L33: Messi | M33: Mist
E34: 31 | G34: Muddying | H34: Gallium | L34: Medusa | M34: Mud
E35: 32 | G35: Mining | H35: Germanium | L35: Minion | M35: Moon
E36: 33 | G36: Miming | H36: Arsenic | L36: Mummy | M36: Memo
E37: 34 | G37: Marrying | H37: Selenium | L37: Mario | M37: Hammer
E38: 35 | G38: Mailing | H38: Bromine | L38: Molly | M38: Mail
E39: 36 | G39: Mashing | H39: Krypton | L39: Michael Jackson | M39: Mash
E40: 37 | G40: Making | H40: Rubidium | L40: Mickey | M40: Mug
...

Sheet Sheet3
A1: =TEXT(Sheet1!E1, "000") -> Number | B1: =Sheet1!F1 -> Person | C1: =Sheet1!H1 -> Object
A2: =TEXT(Sheet1!E2, "000") -> - | B2: =Sheet1!F2 -> Magician | C2: =Sheet1!H2 -> Wand
A3: =TEXT(Sheet1!E3, "000") -> 000 | B3: =Sheet1!F3 | C3: =Sheet1!H3 -> Void/Vacuum
A4: =TEXT(Sheet1!E4, "000") -> 001 | B4: =Sheet1!F4 | C4: =Sheet1!H4 -> Hydrogen
A5: =TEXT(Sheet1!E5, "000") -> 002 | B5: =Sheet1!F5 | C5: =Sheet1!H5 -> Helium
A6: =TEXT(Sheet1!E6, "000") -> 003 | B6: =Sheet1!F6 | C6: =Sheet1!H6 -> Lithium
A7: =TEXT(Sheet1!E7, "000") -> 004 | B7: =Sheet1!F7 | C7: =Sheet1!H7 -> Beryllium
A8: =TEXT(Sheet1!E8, "000") -> 005 | B8: =Sheet1!F8 | C8: =Sheet1!H8 -> Boron
A9: =TEXT(Sheet1!E9, "000") -> 006 | B9: =Sheet1!F9 | C9: =Sheet1!H9 -> Carbon
A10: =TEXT(Sheet1!E10, "000") -> 007 | B10: =Sheet1!F10 | C10: =Sheet1!H10 -> Nitrogen
A11: =TEXT(Sheet1!E11, "000") -> 008 | B11: =Sheet1!F11 | C11: =Sheet1!H11 -> Oxygen
A12: =TEXT(Sheet1!E12, "000") -> 009 | B12: =Sheet1!F12 | C12: =Sheet1!H12 -> Fluorine
... A972: =TEXT(Sheet1!E972, "000") -> 969 | B972: =Sheet1!F972 | C972: =Sheet1!H972 -> Bone Cell
A973: =TEXT(Sheet1!E973, "000") -> 970 | B973: =Sheet1!F973 -> Snapchat Ghost | C973: =Sheet1!K973 -> Cell Membrane
A974: =TEXT(Sheet1!E974, "000") -> 971 | B974: =Sheet1!F974 -> Pringles Man | C974: =Sheet1!K974 -> Cytoplasma
A975: =TEXT(Sheet1!E975, "000") -> 972 | B975: =Sheet1!F975 -> Duolingo | C975: =Sheet1!K975 -> Nucleus
A976: =TEXT(Sheet1!E976, "000") -> 973 | B976: =Sheet1!F976 -> Wumpus | C976: =Sheet1!K976 -> Mitochondria
A977: =TEXT(Sheet1!E977, "000") -> 974 | B977: =Sheet1!F977 -> Reddit Alien | C977: =Sheet1!K977 -> Ribosome
A978: =TEXT(Sheet1!E978, "000") -> 975 | B978: =Sheet1!F978 -> Android | C978: =Sheet1!K978 -> Lysosome
A979: =TEXT(Sheet1!E979, "000") -> 976 | B979: =Sheet1!F979 -> Hatsune Miku | C979: =Sheet1!K979 -> Chromatine
A980: =TEXT(Sheet1!E980, "000") -> 977 | B980: =Sheet1!F980 -> Clippy | C980: =Sheet1!K980 -> Golgi Body
A981: =TEXT(Sheet1!E981, "000") -> 978 | B981: =Sheet1!F981 -> Github Octocat | C981: =Sheet1!K981 -> Vacuole
A982: =TEXT(Sheet1!E982, "000") -> 979 | B982: =Sheet1!F982 -> Bonzi Buddy | C982: =Sheet1!K982 -> Endoplasmatic Reticulum
A983: =TEXT(Sheet1!E983, "000") -> 980 | B983: =Sheet1!F983 | C983: =Sheet1!H983 -> Eyes
A984: =TEXT(Sheet1!E984, "000") -> 981 | B984: =Sheet1!F984 | C984: =Sheet1!H984 -> Tongue
A985: =TEXT(Sheet1!E985, "000") -> 982 | B985: =Sheet1!F985 | C985: =Sheet1!H985 -> Nose
A986: =TEXT(Sheet1!E986, "000") -> 983 | B986: =Sheet1!F986 | C986: =Sheet1!H986 -> Ears
A987: =TEXT(Sheet1!E987, "000") -> 984 | B987: =Sheet1!F987 | C987: =Sheet1!H987 -> Inner Ear
A988: =TEXT(Sheet1!E988, "000") -> 985 | B988: =Sheet1!F988 | C988: =Sheet1!H988 -> Nervous System
A989: =TEXT(Sheet1!E989, "000") -> 986 | B989: =Sheet1!F989 | C989: =Sheet1!H989 -> Nose Hairs
A990: =TEXT(Sheet1!E990, "000") -> 987 | B990: =Sheet1!F990 | C990: =Sheet1!H990 -> Skin
A991: =TEXT(Sheet1!E991, "000") -> 988 | B991: =Sheet1!F991 | C991: =Sheet1!H991 -> Finger
A992: =TEXT(Sheet1!E992, "000") -> 989 | B992: =Sheet1!F992 | C992: =Sheet1!H992 -> Tastebud
A993: =TEXT(Sheet1!E993, "000") -> 990 | B993: =Sheet1!F993 | C993: =Sheet1!H993 -> Fingernail
A994: =TEXT(Sheet1!E994, "000") -> 991 | B994: =Sheet1!F994 | C994: =Sheet1!H994 -> Toenail
... A1002: =TEXT(Sheet1!E1002, "000") -> 999 | B1002: =Sheet1!F1002 | C1002: =Sheet1!H1002 -> DNA
